<robot
  name="jaka1012">
  <link
    name="base_link">
    <inertial>
      <origin
        xyz="-7.58274157915068E-05 0.000813871580432111 0.00873312635876805"
        rpy="0 0 0" />
      <mass
        value="0.272054564730731" />
      <inertia
        ixx="0"
        ixy="0"
        ixz="0"
        iyy="0"
        iyz="0"
        izz="0" />
    </inertial>
    <visual>
      <origin
        xyz="0 0 0"
        rpy="0 0 0" />
      <geometry>
        <mesh
          filename="package://jaka1012/meshes/base_link.STL" />
      </geometry>
      <material
        name="">
        <color
          rgba="1 1 1 1" />
      </material>
    </visual>
    <collision>
      <origin
        xyz="0 0 0"
        rpy="0 0 0" />
      <geometry>
        <mesh
          filename="package://jaka1012/meshes/base_link.STL" />
      </geometry>
    </collision>
  </link>
  <link
    name="link_1">
    <inertial>
      <origin
        xyz="4.91155796940399E-06 0.00346307580581019 0.00783360553776767"
        rpy="0 0 0" />
      <mass
        value="0.433362442716473" />
      <inertia
        ixx="0.00103274325449067"
        ixy="-1.38712647217067E-09"
        ixz="1.30736026433442E-08"
        iyy="0.00101774766498695"
        iyz="6.90341995612015E-05"
        izz="1.49955898881909E-05" />
    </inertial>
    <visual>
      <origin
        xyz="0 0 0"
        rpy="0 0 0" />
      <geometry>
        <mesh
          filename="package://jaka1012/meshes/link_1.STL" />
      </geometry>
      <material
        name="">
        <color
          rgba="1 1 1 1" />
      </material>
    </visual>
    <collision>
      <origin
        xyz="0 0 0"
        rpy="0 0 0" />
      <geometry>
        <mesh
          filename="package://jaka1012/meshes/link_1.STL" />
      </geometry>
    </collision>
  </link>
  <joint
    name="joint_1"
    type="revolute">
    <origin
      xyz="0 0.00092912 0.094295"
      rpy="-1.9722E-31 -3.9443E-31 -2.3447E-10" />
    <parent
      link="base_link" />
    <child
      link="link_1" />
    <axis
      xyz="0 0 1" />
    <limit
      effort="0"
      velocity="0" />
  </joint>
  <link
    name="link_2">
    <inertial>
      <origin
        xyz="0.142592657321296 0.15235334308642 0.0882499254872059"
        rpy="0 0 0" />
      <mass
        value="1.50129580331979" />
      <inertia
        ixx="0.0260687606124206"
        ixy="-5.84341048204956E-10"
        ixz="1.09393844763966E-09"
        iyy="0.00859870826843709"
        iyz="-0.011288161576065"
        izz="0.0216328907309336" />
    </inertial>
    <visual>
      <origin
        xyz="0 0 0"
        rpy="0 0 0" />
      <geometry>
        <mesh
          filename="package://jaka1012/meshes/link_2.STL" />
      </geometry>
      <material
        name="">
        <color
          rgba="1 1 1 1" />
      </material>
    </visual>
    <collision>
      <origin
        xyz="0 0 0"
        rpy="0 0 0" />
      <geometry>
        <mesh
          filename="package://jaka1012/meshes/link_2.STL" />
      </geometry>
    </collision>
  </link>
  <joint
    name="joint_2"
    type="revolute">
    <origin
      xyz="0.00025547 -0.00092912 0.35227"
      rpy="-2.0944 -7.2023E-16 1.5708" />
    <parent
      link="link_1" />
    <child
      link="link_2" />
    <axis
      xyz="0 -1 0" />
    <limit
      effort="0"
      velocity="0" />
  </joint>
  <link
    name="Link_3">
    <inertial>
      <origin
        xyz="0.0177651076640887 0.30520685007342 0.303842277866525"
        rpy="0 0 0" />
      <mass
        value="0.704144615698279" />
      <inertia
        ixx="0.00957933521551889"
        ixy="3.89089461416199E-08"
        ixz="0.000511256365163714"
        iyy="0.00976804795623844"
        iyz="-5.54184649849505E-08"
        izz="0.000188712824815712" />
    </inertial>
    <visual>
      <origin
        xyz="0 0 0"
        rpy="0 0 0" />
      <geometry>
        <mesh
          filename="package://jaka1012/meshes/Link_3.STL" />
      </geometry>
      <material
        name="">
        <color
          rgba="1 1 1 1" />
      </material>
    </visual>
    <collision>
      <origin
        xyz="0 0 0"
        rpy="0 0 0" />
      <geometry>
        <mesh
          filename="package://jaka1012/meshes/Link_3.STL" />
      </geometry>
    </collision>
  </link>
  <joint
    name="joint_3"
    type="revolute">
    <origin
      xyz="0 0.17557 0.30546"
      rpy="-2.618 5.5511E-16 5.5511E-16" />
    <parent
      link="link_2" />
    <child
      link="Link_3" />
    <axis
      xyz="0 -1 0" />
    <limit
      effort="0"
      velocity="0" />
  </joint>
  <link
    name="link_4">
    <inertial>
      <origin
        xyz="0.105695426990796 0.305774990570479 0.483270026475343"
        rpy="0 0 0" />
      <mass
        value="0.148546138588578" />
      <inertia
        ixx="0.000161066406102884"
        ixy="-2.3774180911987E-06"
        ixz="1.34483022547569E-05"
        iyy="0.000160010056282085"
        iyz="2.75105985218499E-05"
        izz="8.63293529558298E-06" />
    </inertial>
    <visual>
      <origin
        xyz="0 0 0"
        rpy="0 0 0" />
      <geometry>
        <mesh
          filename="package://jaka1012/meshes/link_4.STL" />
      </geometry>
      <material
        name="">
        <color
          rgba="1 1 1 1" />
      </material>
    </visual>
    <collision>
      <origin
        xyz="0 0 0"
        rpy="0 0 0" />
      <geometry>
        <mesh
          filename="package://jaka1012/meshes/link_4.STL" />
      </geometry>
    </collision>
  </link>
  <joint
    name="joint_4"
    type="fixed">
    <origin
      xyz="0 -0.079843 0.06039"
      rpy="-0.17453 8.8818E-16 -9.7145E-17" />
    <parent
      link="Link_3" />
    <child
      link="link_4" />
    <axis
      xyz="0 -1 0" />
  </joint>
  <link
    name="link_5">
    <inertial>
      <origin
        xyz="0.109013971319051 0.292941707052944 0.578942428981851"
        rpy="0 0 0" />
      <mass
        value="0.160232457061653" />
      <inertia
        ixx="0.000179088053824111"
        ixy="-1.0727653982616E-06"
        ixz="-2.04117656478202E-07"
        iyy="6.49147786368063E-06"
        iyz="-3.23343510436684E-05"
        izz="0.000172623910445256" />
    </inertial>
    <visual>
      <origin
        xyz="0 0 0"
        rpy="0 0 0" />
      <geometry>
        <mesh
          filename="package://jaka1012/meshes/link_5.STL" />
      </geometry>
      <material
        name="">
        <color
          rgba="1 1 1 1" />
      </material>
    </visual>
    <collision>
      <origin
        xyz="0 0 0"
        rpy="0 0 0" />
      <geometry>
        <mesh
          filename="package://jaka1012/meshes/link_5.STL" />
      </geometry>
    </collision>
  </link>
  <joint
    name="joint_5"
    type="fixed">
    <origin
      xyz="0.0022055 -0.00060813 -0.00010723"
      rpy="-2.8007E-06 -0.00099381 0.0056362" />
    <parent
      link="link_4" />
    <child
      link="link_5" />
    <axis
      xyz="0 0 1" />
  </joint>
  <link
    name="link_6">
    <inertial>
      <origin
        xyz="7.17480102292445E-05 0.0011523497867893 -0.0147687941484504"
        rpy="0 0 0" />
      <mass
        value="0.0718266452529442" />
      <inertia
        ixx="0"
        ixy="0"
        ixz="0"
        iyy="0"
        iyz="0"
        izz="0" />
    </inertial>
    <visual>
      <origin
        xyz="0 0 0"
        rpy="0 0 0" />
      <geometry>
        <mesh
          filename="package://jaka1012/meshes/link_6.STL" />
      </geometry>
      <material
        name="">
        <color
          rgba="1 1 1 1" />
      </material>
    </visual>
    <collision>
      <origin
        xyz="0 0 0"
        rpy="0 0 0" />
      <geometry>
        <mesh
          filename="package://jaka1012/meshes/link_6.STL" />
      </geometry>
    </collision>
  </link>
  <joint
    name="joint_6"
    type="continuous">
    <origin
      xyz="0.10851 0.20491 0.56579"
      rpy="1.7655 0.45721 0.081046" />
    <parent
      link="link_5" />
    <child
      link="link_6" />
    <axis
      xyz="-1 0 0" />
  </joint>
</robot>