<?xml version="1.0"?>
<robot name="jakaUr">

<material name="blue">
    <color rgba="0 0 0.8 1"/>
  </material>

  <material name="black">
    <color rgba="0 0 0 1"/>
  </material>

  <material name="white">
    <color rgba="1 1 1 1"/>
  </material>

  <link name="base_link">
    <visual>
      <geometry>
        <mesh filename="package://urdf_tutorial/mesh/P1.STL>
      </geometry>
      <material name="blue"/>
    </visual>
  </link>

  <link name="link_1">
    <visual>
      <geometry>
         <mesh filename="package://urdf_tutorial/mesh/p2.STL>
      </geometry>
      <origin rpy="0 0 0" xyz="0 0 0.94"/>
      <material name="white"/>
    </visual>
  </link>

  <joint name="joint_1" type="revolute">
    <parent link="base_link"/>
    <child link="link_1"/>
    <origin xyz="0 0 0.94"/>
  </joint>

  <link name="link_2">
    <visual>
      <geometry>
         <mesh filename="package://urdf_tutorial/mesh/p3.STL>
      </geometry>
      <material name="white"/>
    </visual>
  </link>

  <joint name="joint_2" type="revolute"
    <parent link="link_1"/>
    <child link="link_2"/>
    <origin xyz="0 0 -0.6"/>
  </joint>

  <link name="link_3">
    <visual>
      <origin rpy="1.57075 0 0" xyz="0 0 0"/>
      <geometry>
         <mesh filename="package://urdf_tutorial/mesh/p4.STL>
      </geometry>
      <material name="black"/>
      <origin rpy="0 0 0" xyz="0 0 0"/>
    </visual>
  </link>

  <joint name="joint_3" type="revolute">
    <parent link="link_2"/>
    <child link="link_3"/>
    <origin rpy="0 0 0" xyz="0 0 -0.085"/>
  </joint>

  <link name="link_4">
    <visual>
      <origin rpy="0 0 0" xyz="0 0 0"/>
      <geometry>
        <mesh filename="package://urdf_tutorial/mesh/p5.STL> 
      </geometry>
      <material name="black"/>
    </visual>
  </link>

  <joint name="joint_4" type="revolute">
    <parent link="link_3"/>
    <child link="link_4"/>
    <origin rpy="0 0 0" xyz="0 0 0/>
  </joint>

  <link name="link_5">
    <visual>
      <geometry>
         <mesh filename="package://urdf_tutorial/mesh/p6.STL>
      </geometry>
      <origin rpy="0 0 0" xyz="0 0 0"/>
      <material name="white"/>
    </visual>
  </link>

  <joint name="joint_5" type="revolute">
    <parent link="link_4"/>
    <child link="link_5"/>
    <origin xyz="0 0.22 0.25"/>
  </joint>

  <link name="link_6">
    <visual>
      <geometry>
         <mesh filename="package://urdf_tutorial/mesh/p7.STL>
      </geometry>
      <material name="white"/>
    </visual>
  </link>

  <joint name="joint_6" type="revolute">
    <parent link="link_5"/>
    <child link="link_6"/>
    <origin xyz="0 0 -0.6"/>
  </joint>

</robot>
