<?xml version="1.0" ?>
<!-- =================================================================================== -->
<!-- |    This document was autogenerated by xacro from jaka.urdf.xacro                | -->
<!-- |    EDITING THIS FILE BY HAND IS NOT RECOMMENDED                                 | -->
<!-- =================================================================================== -->
<robot name="jakaUr" xmlns:xacro="http://www.ros.org/wiki/xacro">
  <material name="blue">
    <color rgba="0 0 0.8 1"/>
  </material>
  <material name="black">
    <color rgba="0 0 0 1"/>
  </material>
  <material name="white">
    <color rgba="1 1 1 1"/>
  </material>
  <link name="world">
    <origin rpy="0 0 0" xyz="0 0 -0.2"/>
  </link>
  <joint name="fixed" type="fixed">
    <origin rpy="0 0 0" xyz="0 0 -0.8"/>
    <parent link="world"/>
    <child link="base_link"/>
  </joint>
  <joint name="bottom_joint" type="fixed">
    <origin rpy="0 0 0" xyz="0 0 0"/>
    <parent link="base_link"/>
    <child link="bottom_link"/>
  </joint>
  <link name="bottom_link">
    <!--visual>
      <origin xyz=" 0 0 -0.04"  rpy="0 0 0"/>
      <geometry>

               <box size="1 1 0.02" />

      </geometry>
      <material name="Brown" />
    </visual>

    <collision>
      <origin xyz=" 0 0 -0.04"  rpy="0 0 0"/>
      <geometry>
               <box size="1 1 0.02" />
      </geometry>
      </collision>-->
    <inertial>
      <mass value="5"/>
      <inertia ixx="0.2" ixy="0.0" ixz="0.0" iyy="0.2" iyz="0.0" izz="0.1"/>
    </inertial>
  </link>
  <link name="base_link">
    <visual>
      <origin rpy="0 1.57079632679 0" xyz="0 0 0"/>
      <geometry>
        <mesh filename="package://jaka_ur_description_pkg/mesh/p1.dae"/>
      </geometry>
    </visual>
    <collision>
      <geometry>
        <mesh filename="package://jaka_ur_description_pkg/mesh/p1.dae"/>
      </geometry>
      <origin rpy="0 1.57079632679 0" xyz="0 0 0"/>
    </collision>
    <!--inertial>
      <mass value="5"/>
      <inertia ixx="0.2" ixy="0.0" ixz="0.0" iyy="0.2" iyz="0.0" izz="0.1"/>
    </inertial-->
  </link>
  <link name="link_1">
    <visual>
      <geometry>
        <mesh filename="package://jaka_ur_description_pkg/mesh/p2.dae"/>
      </geometry>
      <origin rpy=" 1.57079632679  0  -1.57079632679" xyz="0 0 0"/>
    </visual>
    <collision>
      <geometry>
        <mesh filename="package://jaka_ur_description_pkg/mesh/p2.dae"/>
      </geometry>
      <origin rpy="1.57079632679 0 -1.57079632679" xyz="0 0 0"/>
    </collision>
    <inertial>
      <mass value="8"/>
      <inertia ixx="0.3" ixy="0.0" ixz="0.0" iyy="0.3" iyz="0.0" izz="0.2"/>
    </inertial>
  </link>
  <joint name="joint_1" type="revolute">
    <axis xyz="0 0 1"/>
    <limit effort="1000" lower="-1.58" upper="1.58" velocity="0.5"/>
    <origin rpy="0 0 0" xyz="0 0 0.094"/>
    <parent link="base_link"/>
    <child link="link_1"/>
  </joint>
  <transmission name="joint_1_trans">
    <type>transmission_interface/SimpleTransmission</type>
    <actuator name="$joint_1_motor">
      <mechanicalReduction>1</mechanicalReduction>
    </actuator>
    <joint name="joint_1">
      <hardwareInterface>PositionJointInterface</hardwareInterface>
    </joint>
  </transmission>
  <link name="link_2">
    <visual>
      <geometry>
        <mesh filename="package://jaka_ur_description_pkg/mesh/p3.dae"/>
      </geometry>
      <origin rpy="1.57079632679 -1.57079632679 2.61799387798" xyz="0 0 0"/>
    </visual>
    <collision>
      <geometry>
        <mesh filename="package://jaka_ur_description_pkg/mesh/p3.dae"/>
      </geometry>
      <origin rpy="1.57079632679 -1.57079632679 2.61799387798 " xyz="0 0 0"/>
    </collision>
    <inertial>
      <mass value="6"/>
      <inertia ixx="0.25" ixy="0.0" ixz="0.0" iyy="0.25" iyz="0.0" izz="0.15"/>
    </inertial>
  </link>
  <joint name="joint_2" type="revolute">
    <axis xyz="0 0 1"/>
    <limit effort="1000" lower="-1.58" upper="3.58" velocity="0.5"/>
    <origin rpy="1.57079632679 0 0" xyz="0 0 0"/>
    <parent link="link_1"/>
    <child link="link_2"/>
  </joint>
  <transmission name="joint_2_trans">
    <type>transmission_interface/SimpleTransmission</type>
    <actuator name="$joint_2_motor">
      <mechanicalReduction>1</mechanicalReduction>
    </actuator>
    <joint name="joint_2">
      <hardwareInterface>PositionJointInterface</hardwareInterface>
    </joint>
  </transmission>
  <link name="link_3">
    <visual>
      <geometry>
        <mesh filename="package://jaka_ur_description_pkg/mesh/p4.dae"/>
      </geometry>
      <origin rpy="0 0 -1.57079632679" xyz="0 0 0.0135"/>
    </visual>
    <collision>
      <geometry>
        <mesh filename="package://jaka_ur_description_pkg/mesh/p4.dae"/>
      </geometry>
      <origin rpy="0 0 -1.57079632679" xyz="0 0 0.0135"/>
    </collision>
    <inertial>
      <mass value="8"/>
      <inertia ixx="0.3" ixy="0.0" ixz="0.0" iyy="0.3" iyz="0.0" izz="0.2"/>
    </inertial>
  </link>
  <joint name="joint_3" type="revolute">
    <axis xyz="0 0 1"/>
    <limit effort="1000" lower="-1.58" upper="3.58" velocity="0.5"/>
    <origin rpy="0 0 0" xyz="0.353 0 0"/>
    <parent link="link_2"/>
    <child link="link_3"/>
  </joint>
  <transmission name="joint_3_trans">
    <type>transmission_interface/SimpleTransmission</type>
    <actuator name="joint_3_motor">
      <mechanicalReduction>1</mechanicalReduction>
    </actuator>
    <joint name="joint_3">
      <hardwareInterface>PositionJointInterface</hardwareInterface>
    </joint>
  </transmission>
  <link name="link_4">
    <visual>
      <geometry>
        <mesh filename="package://jaka_ur_description_pkg/mesh/p5.dae"/>
      </geometry>
      <origin rpy="-1.57079632679 0 1.57079632679" xyz="0 0 0"/>
    </visual>
    <collision>
      <geometry>
        <mesh filename="package://jaka_ur_description_pkg/mesh/p5.dae"/>
      </geometry>
      <origin rpy="-1.57079632679 0 1.57079632679" xyz="0 0 0"/>
    </collision>
    <inertial>
      <mass value="5"/>
      <inertia ixx="0.2" ixy="0.0" ixz="0.0" iyy="0.2" iyz="0.0" izz="0.15"/>
    </inertial>
  </link>
  <joint name="joint_4" type="revolute">
    <axis xyz="0 0 1"/>
    <limit effort="1000" lower="-1.58" upper="3.58" velocity="0.5"/>
    <origin rpy="0 0 0" xyz="0.31 0 0.109"/>
    <parent link="link_3"/>
    <child link="link_4"/>
  </joint>
  <transmission name="joint_4_trans">
    <type>transmission_interface/SimpleTransmission</type>
    <actuator name="joint_4_motor">
      <mechanicalReduction>1</mechanicalReduction>
    </actuator>
    <joint name="joint_4">
      <hardwareInterface>PositionJointInterface</hardwareInterface>
    </joint>
  </transmission>
  <link name="link_5">
    <visual>
      <geometry>
        <mesh filename="package://jaka_ur_description_pkg/mesh/p6.dae"/>
      </geometry>
      <origin rpy="3.14159265358 0 -1.57079632679" xyz="0 0 0"/>
    </visual>
    <collision>
      <geometry>
        <mesh filename="package://jaka_ur_description_pkg/mesh/p6.dae"/>
      </geometry>
      <origin rpy="3.14159265358 0 -1.57079632679" xyz="0 0 0"/>
    </collision>
    <inertial>
      <mass value="4"/>
      <inertia ixx="0.1" ixy="0.0" ixz="0.0" iyy="0.1" iyz="0.0" izz="0.07"/>
    </inertial>
  </link>
  <joint name="joint_5" type="revolute">
    <axis xyz="0 0 1"/>
    <limit effort="1000" lower="-1.58" upper="3.58" velocity="0.5"/>
    <origin rpy="1.57079632679 0 0" xyz="0 -0.0955 0"/>
    <parent link="link_4"/>
    <child link="link_5"/>
  </joint>
  <transmission name="joint_5_trans">
    <type>transmission_interface/SimpleTransmission</type>
    <actuator name="joint_5_motor">
      <mechanicalReduction>1</mechanicalReduction>
    </actuator>
    <joint name="joint_5">
      <hardwareInterface>PositionJointInterface</hardwareInterface>
    </joint>
  </transmission>
  <link name="link_6">
    <visual>
      <geometry>
        <mesh filename="package://jaka_ur_description_pkg/mesh/p7.dae"/>
      </geometry>
      <origin rpy="-3.14159265358 0 0" xyz="0 0 0.03"/>
    </visual>
    <collision>
      <geometry>
        <mesh filename="package://jaka_ur_description_pkg/mesh/p7.dae"/>
      </geometry>
      <origin rpy="-3.14159265358 0 0" xyz="0 0 0.03"/>
    </collision>
    <inertial>
      <mass value="2"/>
      <inertia ixx="0.07" ixy="0.0" ixz="0.0" iyy="0.07" iyz="0.0" izz="0.04"/>
    </inertial>
  </link>
  <joint name="joint_6" type="revolute">
    <axis xyz="0 0 1"/>
    <limit effort="1000" lower="-1.58" upper="3.58" velocity="0.5"/>
    <origin rpy="1.57079632679 0 0" xyz="0 0.085 0"/>
    <parent link="link_5"/>
    <child link="link_6"/>
  </joint>
  <transmission name="joint_6_trans">
    <type>transmission_interface/SimpleTransmission</type>
    <actuator name="joint_6_motor">
      <mechanicalReduction>1</mechanicalReduction>
    </actuator>
    <joint name="joint_6">
      <hardwareInterface>PositionJointInterface</hardwareInterface>
    </joint>
  </transmission>
  <!-- ros_control plugin -->
  <gazebo>
    <plugin filename="libgazebo_ros_control.so" name="gazebo_ros_control">
      <robotNamespace>/jakaUr</robotNamespace>
    </plugin>
  </gazebo>
</robot>

